Workbook

Sheet Tổng hợp điểm
B1: ĐIỂM THI HK1-2018-2019 (CT428)
B2: Ma CB | C2: 1043 | D2: Ho va ten | F2: Nguyen Minh Trung
B3: Ma MH | C3: CT428 | D3: Ma NH | F3: 8
B4: Nam hoc | C4: 2020-2021 | D4: Hoc ky | F4: 1
A6: STT | B6: Mã SV | C6: Họ và Tên | D6: Điểm TH 1 | E6: Điểm TH 2 | F6: Điểm TH 3 | G6: Điểm BT lớn | H6: Điểm LT | I6: Điểm tổng | J6: Điểm theo thang điểm 10 | K6: Điểm chữ
A7: 1 | B7: 0B1505719 | C7: =VLOOKUP(RIGHT('Tổng hợp điểm'!B7,8),'Điểm thực hành các buổi'!$B$3:$F$41,2,1) -> Nguyễn Phước Hiếu | D7: =VLOOKUP(RIGHT('Tổng hợp điểm'!B7,8),'Điểm thực hành các buổi'!$B$3:$F$41,3,1) -> 0.45 | E7: =VLOOKUP(RIGHT('Tổng hợp điểm'!B7,8),'Điểm thực hành các buổi'!$B$3:$F$41,4,1) -> 0.25 | F7: =VLOOKUP(RIGHT('Tổng hợp điểm'!B7,8),'Điểm thực hành các buổi'!$B$3:$F$41,5,1) -> 0.3 | G7: =VLOOKUP(RIGHT('Tổng hợp điểm'!B7,8),'Điểm bài tập lớn'!$B$3:$D$41,3,1) -> 0.5 | H7: =VLOOKUP(RIGHT('Tổng hợp điểm'!B7,8),'Điểm lý thuyết'!$B$3:$D$41,3,1) -> 4.2 | I7: =ROUND(IF(H7=-3,0,D7+E7+F7+G7+H7*0.6),1) -> 4 | J7: =ROUND(IF(OR(G7=0,VALUE(LEFT(B7,1))>2),0,I7+IF(LEFT(B7,1)="0",1,IF(LEFT(B7,1)="1",0.5,0.25))),1) -> 5 | K7: =VLOOKUP(J7,'Các bảng tham chiếu & Thống kê'!$A$3:$B$10,2,1) -> D+
A8: 2 | B8: 1B1505915 | C8: =VLOOKUP(RIGHT('Tổng hợp điểm'!B8,8),'Điểm thực hành các buổi'!$B$3:$F$41,2,1) -> Lý Minh Trí | D8: =VLOOKUP(RIGHT('Tổng hợp điểm'!B8,8),'Điểm thực hành các buổi'!$B$3:$F$41,3,1) -> 0.5 | E8: =VLOOKUP(RIGHT('Tổng hợp điểm'!B8,8),'Điểm thực hành các buổi'!$B$3:$F$41,4,1) -> 0.35 | F8: =VLOOKUP(RIGHT('Tổng hợp điểm'!B8,8),'Điểm thực hành các buổi'!$B$3:$F$41,5,1) -> 0.4 | G8: =VLOOKUP(RIGHT('Tổng hợp điểm'!B8,8),'Điểm bài tập lớn'!$B$3:$D$41,3,1) -> 1 | H8: =VLOOKUP(RIGHT('Tổng hợp điểm'!B8,8),'Điểm lý thuyết'!$B$3:$D$41,3,1) -> 5.8 | I8: =ROUND(IF(H8=-3,0,D8+E8+F8+G8+H8*0.6),1) -> 5.7 | J8: =ROUND(IF(OR(G8=0,VALUE(LEFT(B8,1))>2),0,I8+IF(LEFT(B8,1)="0",1,IF(LEFT(B8,1)="1",0.5,0.25))),1) -> 6.2 | K8: =VLOOKUP(J8,'Các bảng tham chiếu & Thống kê'!$A$3:$B$10,2,1) -> C
A9: 3 | B9: 0B1509874 | C9: =VLOOKUP(RIGHT('Tổng hợp điểm'!B9,8),'Điểm thực hành các buổi'!$B$3:$F$41,2,1) -> Nguyễn Kiều Mi | D9: =VLOOKUP(RIGHT('Tổng hợp điểm'!B9,8),'Điểm thực hành các buổi'!$B$3:$F$41,3,1) -> 0.25 | E9: =VLOOKUP(RIGHT('Tổng hợp điểm'!B9,8),'Điểm thực hành các buổi'!$B$3:$F$41,4,1) -> 0.25 | F9: =VLOOKUP(RIGHT('Tổng hợp điểm'!B9,8),'Điểm thực hành các buổi'!$B$3:$F$41,5,1) -> 0.3 | G9: =VLOOKUP(RIGHT('Tổng hợp điểm'!B9,8),'Điểm bài tập lớn'!$B$3:$D$41,3,1) -> 0.5 | H9: =VLOOKUP(RIGHT('Tổng hợp điểm'!B9,8),'Điểm lý thuyết'!$B$3:$D$41,3,1) -> 5.8 | I9: =ROUND(IF(H9=-3,0,D9+E9+F9+G9+H9*0.6),1) -> 4.8 | J9: =ROUND(IF(OR(G9=0,VALUE(LEFT(B9,1))>2),0,I9+IF(LEFT(B9,1)="0",1,IF(LEFT(B9,1)="1",0.5,0.25))),1) -> 5.8 | K9: =VLOOKUP(J9,'Các bảng tham chiếu & Thống kê'!$A$3:$B$10,2,1) -> C
A10: 4 | B10: 0B1509929 | C10: =VLOOKUP(RIGHT('Tổng hợp điểm'!B10,8),'Điểm thực hành các buổi'!$B$3:$F$41,2,1) -> Đặng Duy Linh | D10: =VLOOKUP(RIGHT('Tổng hợp điểm'!B10,8),'Điểm thực hành các buổi'!$B$3:$F$41,3,1) -> 0.4 | E10: =VLOOKUP(RIGHT('Tổng hợp điểm'!B10,8),'Điểm thực hành các buổi'!$B$3:$F$41,4,1) -> 0.25 | F10: =VLOOKUP(RIGHT('Tổng hợp điểm'!B10,8),'Điểm thực hành các buổi'!$B$3:$F$41,5,1) -> 0.35 | G10: =VLOOKUP(RIGHT('Tổng hợp điểm'!B10,8),'Điểm bài tập lớn'!$B$3:$D$41,3,1) -> 1 | H10: =VLOOKUP(RIGHT('Tổng hợp điểm'!B10,8),'Điểm lý thuyết'!$B$3:$D$41,3,1) -> 4.5 | I10: =ROUND(IF(H10=-3,0,D10+E10+F10+G10+H10*0.6),1) -> 4.7 | J10: =ROUND(IF(OR(G10=0,VALUE(LEFT(B10,1))>2),0,I10+IF(LEFT(B10,1)="0",1,IF(LEFT(B10,1)="1",0.5,0.25))),1) -> 5.7 | K10: =VLOOKUP(J10,'Các bảng tham chiếu & Thống kê'!$A$3:$B$10,2,1) -> C
A11: 5 | B11: 2B1605223 | C11: =VLOOKUP(RIGHT('Tổng hợp điểm'!B11,8),'Điểm thực hành các buổi'!$B$3:$F$41,2,1) -> Lê Thị Trúc Linh | D11: =VLOOKUP(RIGHT('Tổng hợp điểm'!B11,8),'Điểm thực hành các buổi'!$B$3:$F$41,3,1) -> 0.45 | E11: =VLOOKUP(RIGHT('Tổng hợp điểm'!B11,8),'Điểm thực hành các buổi'!$B$3:$F$41,4,1) -> 0.4 | F11: =VLOOKUP(RIGHT('Tổng hợp điểm'!B11,8),'Điểm thực hành các buổi'!$B$3:$F$41,5,1) -> 0.35 | G11: =VLOOKUP(RIGHT('Tổng hợp điểm'!B11,8),'Điểm bài tập lớn'!$B$3:$D$41,3,1) -> 0.75 | H11: =VLOOKUP(RIGHT('Tổng hợp điểm'!B11,8),'Điểm lý thuyết'!$B$3:$D$41,3,1) -> 5.5 | I11: =ROUND(IF(H11=-3,0,D11+E11+F11+G11+H11*0.6),1) -> 5.3 | J11: =ROUND(IF(OR(G11=0,VALUE(LEFT(B11,1))>2),0,I11+IF(LEFT(B11,1)="0",1,IF(LEFT(B11,1)="1",0.5,0.25))),1) -> 5.6 | K11: =VLOOKUP(J11,'Các bảng tham chiếu & Thống kê'!$A$3:$B$10,2,1) -> C
A12: 6 | B12: 0B1605235 | C12: =VLOOKUP(RIGHT('Tổng hợp điểm'!B12,8),'Điểm thực hành các buổi'!$B$3:$F$41,2,1) -> Phạm Thị Huỳnh Như | D12: =VLOOKUP(RIGHT('Tổng hợp điểm'!B12,8),'Điểm thực hành các buổi'!$B$3:$F$41,3,1) -> 0.4 | E12: =VLOOKUP(RIGHT('Tổng hợp điểm'!B12,8),'Điểm thực hành các buổi'!$B$3:$F$41,4,1) -> 0.45 | F12: =VLOOKUP(RIGHT('Tổng hợp điểm'!B12,8),'Điểm thực hành các buổi'!$B$3:$F$41,5,1) -> 0.5 | G12: =VLOOKUP(RIGHT('Tổng hợp điểm'!B12,8),'Điểm bài tập lớn'!$B$3:$D$41,3,1) -> 1.2 | H12: =VLOOKUP(RIGHT('Tổng hợp điểm'!B12,8),'Điểm lý thuyết'!$B$3:$D$41,3,1) -> 7.5 | I12: =ROUND(IF(H12=-3,0,D12+E12+F12+G12+H12*0.6),1) -> 7.1 | J12: =ROUND(IF(OR(G12=0,VALUE(LEFT(B12,1))>2),0,I12+IF(LEFT(B12,1)="0",1,IF(LEFT(B12,1)="1",0.5,0.25))),1) -> 8.1 | K12: =VLOOKUP(J12,'Các bảng tham chiếu & Thống kê'!$A$3:$B$10,2,1) -> B+
A13: 7 | B13: 0B1605249 | C13: =VLOOKUP(RIGHT('Tổng hợp điểm'!B13,8),'Điểm thực hành các buổi'!$B$3:$F$41,2,1) -> Lê Minh Thông | D13: =VLOOKUP(RIGHT('Tổng hợp điểm'!B13,8),'Điểm thực hành các buổi'!$B$3:$F$41,3,1) -> 0.4 | E13: =VLOOKUP(RIGHT('Tổng hợp điểm'!B13,8),'Điểm thực hành các buổi'!$B$3:$F$41,4,1) -> 0.4 | F13: =VLOOKUP(RIGHT('Tổng hợp điểm'!B13,8),'Điểm thực hành các buổi'!$B$3:$F$41,5,1) -> 0.4 | G13: =VLOOKUP(RIGHT('Tổng hợp điểm'!B13,8),'Điểm bài tập lớn'!$B$3:$D$41,3,1) -> 1 | H13: =VLOOKUP(RIGHT('Tổng hợp điểm'!B13,8),'Điểm lý thuyết'!$B$3:$D$41,3,1) -> 5.3 | I13: =ROUND(IF(H13=-3,0,D13+E13+F13+G13+H13*0.6),1) -> 5.4 | J13: =ROUND(IF(OR(G13=0,VALUE(LEFT(B13,1))>2),0,I13+IF(LEFT(B13,1)="0",1,IF(LEFT(B13,1)="1",0.5,0.25))),1) -> 6.4 | K13: =VLOOKUP(J13,'Các bảng tham chiếu & Thống kê'!$A$3:$B$10,2,1) -> C
A14: 8 | B14: 0B1605257 | C14: =VLOOKUP(RIGHT('Tổng hợp điểm'!B14,8),'Điểm thực hành các buổi'!$B$3:$F$41,2,1) -> Quách Thu Vân | D14: =VLOOKUP(RIGHT('Tổng hợp điểm'!B14,8),'Điểm thực hành các buổi'!$B$3:$F$41,3,1) -> 0.45 | E14: =VLOOKUP(RIGHT('Tổng hợp điểm'!B14,8),'Điểm thực hành các buổi'!$B$3:$F$41,4,1) -> 0.4 | F14: =VLOOKUP(RIGHT('Tổng hợp điểm'!B14,8),'Điểm thực hành các buổi'!$B$3:$F$41,5,1) -> 0.4 | G14: =VLOOKUP(RIGHT('Tổng hợp điểm'!B14,8),'Điểm bài tập lớn'!$B$3:$D$41,3,1) -> 1 | H14: =VLOOKUP(RIGHT('Tổng hợp điểm'!B14,8),'Điểm lý thuyết'!$B$3:$D$41,3,1) -> 7.7 | I14: =ROUND(IF(H14=-3,0,D14+E14+F14+G14+H14*0.6),1) -> 6.9 | J14: =ROUND(IF(OR(G14=0,VALUE(LEFT(B14,1))>2),0,I14+IF(LEFT(B14,1)="0",1,IF(LEFT(B14,1)="1",0.5,0.25))),1) -> 7.9 | K14: =VLOOKUP(J14,'Các bảng tham chiếu & Thống kê'!$A$3:$B$10,2,1) -> B
A15: 9 | B15: 3B1605281 | C15: =VLOOKUP(RIGHT('Tổng hợp điểm'!B15,8),'Điểm thực hành các buổi'!$B$3:$F$41,2,1) -> Trần Thị Kim Khoa | D15: =VLOOKUP(RIGHT('Tổng hợp điểm'!B15,8),'Điểm thực hành các buổi'!$B$3:$F$41,3,1) -> 0.5 | E15: =VLOOKUP(RIGHT('Tổng hợp điểm'!B15,8),'Điểm thực hành các buổi'!$B$3:$F$41,4,1) -> 0.4 | F15: =VLOOKUP(RIGHT('Tổng hợp điểm'!B15,8),'Điểm thực hành các buổi'!$B$3:$F$41,5,1) -> 0.4 | G15: =VLOOKUP(RIGHT('Tổng hợp điểm'!B15,8),'Điểm bài tập lớn'!$B$3:$D$41,3,1) -> 1 | H15: =VLOOKUP(RIGHT('Tổng hợp điểm'!B15,8),'Điểm lý thuyết'!$B$3:$D$41,3,1) -> -3 | I15: =ROUND(IF(H15=-3,0,D15+E15+F15+G15+H15*0.6),1) -> 0 | J15: =ROUND(IF(OR(G15=0,VALUE(LEFT(B15,1))>2),0,I15+IF(LEFT(B15,1)="0",1,IF(LEFT(B15,1)="1",0.5,0.25))),1) -> 0 | K15: =VLOOKUP(J15,'Các bảng tham chiếu & Thống kê'!$A$3:$B$10,2,1) -> F
A16: 10 | B16: 0B1605285 | C16: =VLOOKUP(RIGHT('Tổng hợp điểm'!B16,8),'Điểm thực hành các buổi'!$B$3:$F$41,2,1) -> Huỳnh Thị Hồng Loan | D16: =VLOOKUP(RIGHT('Tổng hợp điểm'!B16,8),'Điểm thực hành các buổi'!$B$3:$F$41,3,1) -> 0.45 | E16: =VLOOKUP(RIGHT('Tổng hợp điểm'!B16,8),'Điểm thực hành các buổi'!$B$3:$F$41,4,1) -> 0.4 | F16: =VLOOKUP(RIGHT('Tổng hợp điểm'!B16,8),'Điểm thực hành các buổi'!$B$3:$F$41,5,1) -> 0.45 | G16: =VLOOKUP(RIGHT('Tổng hợp điểm'!B16,8),'Điểm bài tập lớn'!$B$3:$D$41,3,1) -> 0 | H16: =VLOOKUP(RIGHT('Tổng hợp điểm'!B16,8),'Điểm lý thuyết'!$B$3:$D$41,3,1) -> 6.8 | I16: =ROUND(IF(H16=-3,0,D16+E16+F16+G16+H16*0.6),1) -> 5.4 | J16: =ROUND(IF(OR(G16=0,VALUE(LEFT(B16,1))>2),0,I16+IF(LEFT(B16,1)="0",1,IF(LEFT(B16,1)="1",0.5,0.25))),1) -> 0 | K16: =VLOOKUP(J16,'Các bảng tham chiếu & Thống kê'!$A$3:$B$10,2,1) -> F
A17: 11 | B17: 0B1605291 | C17: =VLOOKUP(RIGHT('Tổng hợp điểm'!B17,8),'Điểm thực hành các buổi'!$B$3:$F$41,2,1) -> Trần Thị Thanh Nguyên | D17: =VLOOKUP(RIGHT('Tổng hợp điểm'!B17,8),'Điểm thực hành các buổi'!$B$3:$F$41,3,1) -> 0.45 | E17: =VLOOKUP(RIGHT('Tổng hợp điểm'!B17,8),'Điểm thực hành các buổi'!$B$3:$F$41,4,1) -> 0.4 | F17: =VLOOKUP(RIGHT('Tổng hợp điểm'!B17,8),'Điểm thực hành các buổi'!$B$3:$F$41,5,1) -> 0.4 | G17: =VLOOKUP(RIGHT('Tổng hợp điểm'!B17,8),'Điểm bài tập lớn'!$B$3:$D$41,3,1) -> 0.75 | H17: =VLOOKUP(RIGHT('Tổng hợp điểm'!B17,8),'Điểm lý thuyết'!$B$3:$D$41,3,1) -> 6.3 | I17: =ROUND(IF(H17=-3,0,D17+E17+F17+G17+H17*0.6),1) -> 5.8 | J17: =ROUND(IF(OR(G17=0,VALUE(LEFT(B17,1))>2),0,I17+IF(LEFT(B17,1)="0",1,IF(LEFT(B17,1)="1",0.5,0.25))),1) -> 6.8 | K17: =VLOOKUP(J17,'Các bảng tham chiếu & Thống kê'!$A$3:$B$10,2,1) -> C+
A18: 12 | B18: 1B1605344 | C18: =VLOOKUP(RIGHT('Tổng hợp điểm'!B18,8),'Điểm thực hành các buổi'!$B$3:$F$41,2,1) -> Nguyễn Thị Thúy Nga | D18: =VLOOKUP(RIGHT('Tổng hợp điểm'!B18,8),'Điểm thực hành các buổi'!$B$3:$F$41,3,1) -> 0.3 | E18: =VLOOKUP(RIGHT('Tổng hợp điểm'!B18,8),'Điểm thực hành các buổi'!$B$3:$F$41,4,1) -> 0.5 | F18: =VLOOKUP(RIGHT('Tổng hợp điểm'!B18,8),'Điểm thực hành các buổi'!$B$3:$F$41,5,1) -> 0.45 | G18: =VLOOKUP(RIGHT('Tổng hợp điểm'!B18,8),'Điểm bài tập lớn'!$B$3:$D$41,3,1) -> 0.3 | H18: =VLOOKUP(RIGHT('Tổng hợp điểm'!B18,8),'Điểm lý thuyết'!$B$3:$D$41,3,1) -> 8.3 | I18: =ROUND(IF(H18=-3,0,D18+E18+F18+G18+H18*0.6),1) -> 6.5 | J18: =ROUND(IF(OR(G18=0,VALUE(LEFT(B18,1))>2),0,I18+IF(LEFT(B18,1)="0",1,IF(LEFT(B18,1)="1",0.5,0.25))),1) -> 7 | K18: =VLOOKUP(J18,'Các bảng tham chiếu & Thống kê'!$A$3:$B$10,2,1) -> B
... A45: 39 | B45: 1B1709313 | C45: =VLOOKUP(RIGHT('Tổng hợp điểm'!B45,8),'Điểm thực hành các buổi'!$B$3:$F$41,2,1) -> Võ Thị Thùy Trang | D45: =VLOOKUP(RIGHT('Tổng hợp điểm'!B45,8),'Điểm thực hành các buổi'!$B$3:$F$41,3,1) -> 0.4 | E45: =VLOOKUP(RIGHT('Tổng hợp điểm'!B45,8),'Điểm thực hành các buổi'!$B$3:$F$41,4,1) -> 0.4 | F45: =VLOOKUP(RIGHT('Tổng hợp điểm'!B45,8),'Điểm thực hành các buổi'!$B$3:$F$41,5,1) -> 0.4 | G45: =VLOOKUP(RIGHT('Tổng hợp điểm'!B45,8),'Điểm bài tập lớn'!$B$3:$D$41,3,1) -> 0.75 | H45: =VLOOKUP(RIGHT('Tổng hợp điểm'!B45,8),'Điểm lý thuyết'!$B$3:$D$41,3,1) -> 3.2 | I45: =ROUND(IF(H45=-3,0,D45+E45+F45+G45+H45*0.6),1) -> 3.9 | J45: =ROUND(IF(OR(G45=0,VALUE(LEFT(B45,1))>2),0,I45+IF(LEFT(B45,1)="0",1,IF(LEFT(B45,1)="1",0.5,0.25))),1) -> 4.4 | K45: =VLOOKUP(J45,'Các bảng tham chiếu & Thống kê'!$A$3:$B$10,2,1) -> D

Sheet Điểm thực hành các buổi
A1: Bảng Điểm thực hành các buổi
A2: STT | B2: Mã SV | C2: Họ và Tên | D2: Điểm TH 1 | E2: Điểm TH 2 | F2: Điểm TH 3
A3: 1 | B3: B1505719 | C3: Nguyễn Phước Hiếu | D3: 0.45 | E3: 0.25 | F3: 0.3
A4: 2 | B4: B1505915 | C4: Lý Minh Trí | D4: 0.5 | E4: 0.35 | F4: 0.4
A5: 3 | B5: B1509874 | C5: Nguyễn Kiều Mi | D5: 0.25 | E5: 0.25 | F5: 0.3
A6: 4 | B6: B1509929 | C6: Đặng Duy Linh | D6: 0.4 | E6: 0.25 | F6: 0.35
A7: 5 | B7: B1605223 | C7: Lê Thị Trúc Linh | D7: 0.45 | E7: 0.4 | F7: 0.35
A8: 6 | B8: B1605235 | C8: Phạm Thị Huỳnh Như | D8: 0.4 | E8: 0.45 | F8: 0.5
A9: 7 | B9: B1605249 | C9: Lê Minh Thông | D9: 0.4 | E9: 0.4 | F9: 0.4
A10: 8 | B10: B1605257 | C10: Quách Thu Vân | D10: 0.45 | E10: 0.4 | F10: 0.4
A11: 9 | B11: B1605281 | C11: Trần Thị Kim Khoa | D11: 0.5 | E11: 0.4 | F11: 0.4
A12: 10 | B12: B1605285 | C12: Huỳnh Thị Hồng Loan | D12: 0.45 | E12: 0.4 | F12: 0.45
A13: 11 | B13: B1605291 | C13: Trần Thị Thanh Nguyên | D13: 0.45 | E13: 0.4 | F13: 0.4
A14: 12 | B14: B1605344 | C14: Nguyễn Thị Thúy Nga | D14: 0.3 | E14: 0.5 | F14: 0.45
... A41: 39 | B41: B1709313 | C41: Võ Thị Thùy Trang | D41: 0.4 | E41: 0.4 | F41: 0.4

Sheet Điểm bài tập lớn
A1: Bảng Điểm bài tập lớn
A2: STT | B2: Mã SV | C2: Họ và Tên | D2: Điểm BL lớn
A3: 1 | B3: B1505719 | C3: Nguyễn Phước Hiếu | D3: 0.5
A4: 2 | B4: B1505915 | C4: Lý Minh Trí | D4: 1
A5: 3 | B5: B1509874 | C5: Nguyễn Kiều Mi | D5: 0.5
A6: 4 | B6: B1509929 | C6: Đặng Duy Linh | D6: 1
A7: 5 | B7: B1605223 | C7: Lê Thị Trúc Linh | D7: 0.75
A8: 6 | B8: B1605235 | C8: Phạm Thị Huỳnh Như | D8: 1.2
A9: 7 | B9: B1605249 | C9: Lê Minh Thông | D9: 1
A10: 8 | B10: B1605257 | C10: Quách Thu Vân | D10: 1
A11: 9 | B11: B1605281 | C11: Trần Thị Kim Khoa | D11: 1
A12: 10 | B12: B1605285 | C12: Huỳnh Thị Hồng Loan | D12: 0
A13: 11 | B13: B1605291 | C13: Trần Thị Thanh Nguyên | D13: 0.75
A14: 12 | B14: B1605344 | C14: Nguyễn Thị Thúy Nga | D14: 0.3
... A41: 39 | B41: B1709313 | C41: Võ Thị Thùy Trang | D41: 0.75

Sheet Điểm lý thuyết
A1: Bảng Điểm lý thuyết
A2: STT | B2: Mã SV | C2: Họ và Tên | D2: Điểm lý thuyết
A3: 1 | B3: B1505719 | C3: Nguyễn Phước Hiếu | D3: 4.2
A4: 2 | B4: B1505915 | C4: Lý Minh Trí | D4: 5.8
A5: 3 | B5: B1509874 | C5: Nguyễn Kiều Mi | D5: 5.8
A6: 4 | B6: B1509929 | C6: Đặng Duy Linh | D6: 4.5
A7: 5 | B7: B1605223 | C7: Lê Thị Trúc Linh | D7: 5.5
A8: 6 | B8: B1605235 | C8: Phạm Thị Huỳnh Như | D8: 7.5
A9: 7 | B9: B1605249 | C9: Lê Minh Thông | D9: 5.3
A10: 8 | B10: B1605257 | C10: Quách Thu Vân | D10: 7.7
A11: 9 | B11: B1605281 | C11: Trần Thị Kim Khoa | D11: -3
A12: 10 | B12: B1605285 | C12: Huỳnh Thị Hồng Loan | D12: 6.8
A13: 11 | B13: B1605291 | C13: Trần Thị Thanh Nguyên | D13: 6.3
A14: 12 | B14: B1605344 | C14: Nguyễn Thị Thúy Nga | D14: 8.3
... A41: 39 | B41: B1709313 | C41: Võ Thị Thùy Trang | D41: 3.2

Sheet Các bảng tham chiếu & Thống kê
A1: Bảng quy đổi điểm | E1: Bảng Điểm Chuyên cần
A2: Điểm theo thang điểm 10 | B2: Điểm chữ | C2: Điểm theo thang điểm 4 | E2: Số buổi vắng | F2: Điểm CT
A3: 0 | B3: F | C3: 0 | E3: 0 | F3: 1
A4: 4 | B4: D | C4: 1 | E4: 1 | F4: 0.5
A5: 5 | B5: D+ | C5: 1.5 | E5: 2 | F5: 0.25
A6: 5.5 | B6: C | C6: 2
A7: 6.5 | B7: C+ | C7: 2.5
A8: 7 | B8: B | C8: 3
A9: 8 | B9: B+ | C9: 3.5
A10: 9 | B10: A | C10: 4
A12: Bảng Danh sách Sinh viên | E12: Bảng thống kê theo điểm chữ
A13: STT | B13: Mã SV | C13: Họ và Tên | E13: Điểm chữ | F13: Số lượng sinh viên
A14: 1 | B14: B1607017 | C14: Cao Ngọc Quyên | E14: A | F14: =COUNTIF('Tổng hợp điểm'!$K$7:$K$45,E14) -> 1
A15: 2 | B15: B1509929 | C15: Đặng Duy Linh | E15: B+ | F15: =COUNTIF('Tổng hợp điểm'!$K$7:$K$45,E15) -> 5
A16: 3 | B16: B1706597 | C16: Đặng Trung Kiên | E16: B | F16: =COUNTIF('Tổng hợp điểm'!$K$7:$K$45,E16) -> 7
A17: 4 | B17: B1609773 | C17: Đào Nguyễn Duy Khanh | E17: C+ | F17: =COUNTIF('Tổng hợp điểm'!$K$7:$K$45,E17) -> 6
A18: 5 | B18: B1706589 | C18: Hồ Thị Mỷ Huyền | E18: C | F18: =COUNTIF('Tổng hợp điểm'!$K$7:$K$45,E18) -> 9
A19: 6 | B19: B1706560 | C19: Huỳnh Hoàng Ẩn | E19: D+ | F19: =COUNTIF('Tổng hợp điểm'!$K$7:$K$45,E19) -> 1
A20: 7 | B20: B1706892 | C20: Huỳnh Lê Tỷ | E20: D | F20: =COUNTIF('Tổng hợp điểm'!$K$7:$K$45,E20) -> 1
A21: 8 | B21: B1605285 | C21: Huỳnh Thị Hồng Loan | E21: F | F21: =COUNTIF('Tổng hợp điểm'!$K$7:$K$45,E21) -> 9
A22: 9 | B22: B1706626 | C22: Lại Ngọc Hoàng Phi
A23: 10 | B23: B1706555 | C23: Lê Hồng Quốc Vương | E23: Bảng thống kê SV
A24: 11 | B24: B1605249 | C24: Lê Minh Thông | E24: Số sinh viên điểm BT lớn =0 hoặc điểm LT =-3 | F24: =COUNTIF('Tổng hợp điểm'!$G$7:$G$45,0)+COUNTIF('Tổng hợp điểm'!$H$7:$H$45,-3) -> 9
A25: 12 | B25: B1706550 | C25: Lê Thanh Tùng
A26: 13 | B26: B1605223 | C26: Lê Thị Trúc Linh
A27: 14 | B27: B1505915 | C27: Lý Minh Trí | E27: Số SV có Điểm theo thang điểm 10 >= 7 và có Điểm chữ là B+ hoặc A | F27: =DCOUNT('Tổng hợp điểm'!A6:K45, 'Tổng hợp điểm'!J6, I27:J29) -> 6 | I27: Điểm theo thang điểm 10 | J27: Điểm chữ
A28: 15 | B28: B1704708 | C28: Ngô Hùng Vĩ | I28: >= 7 | J28: ="B+" -> B+
A29: 16 | B29: B1706606 | C29: Ngụy Hữu Lộc | I29: >= 7 | J29: A
A30: 17 | B30: B1706877 | C30: Nguyễn Anh Thư
A31: 18 | B31: B1609533 | C31: Nguyễn Bích Ngân
A32: 19 | B32: B1607025 | C32: Nguyễn Chí Thanh
A33: 20 | B33: B1706655 | C33: Nguyễn Chí Tôn
A34: 21 | B34: B1609759 | C34: Nguyễn Hải Anh
A35: 22 | B35: B1609762 | C35: Nguyễn Hoàng Châu
A36: 23 | B36: B1706630 | C36: Nguyễn Khắc Minh Phúc
A37: 24 | B37: B1509874 | C37: Nguyễn Kiều Mi
A38: 25 | B38: B1709289 | C38: Nguyễn Ngọc Luyến
A39: 26 | B39: B1505719 | C39: Nguyễn Phước Hiếu
A40: 27 | B40: B1706643 | C40: Nguyễn Thị Phương Thảo
A41: 28 | B41: B1605344 | C41: Nguyễn Thị Thúy Nga
...

Sheet Sinh viên <7
A1: STT | B1: Mã SV | C1: Họ và Tên | D1: Điểm TH 1 | E1: Điểm TH 2 | F1: Điểm TH 3 | G1: Điểm BT lớn | H1: Điểm LT | I1: Điểm tổng | J1: Điểm theo thang điểm 10 | K1: Điểm chữ
A2: 1 | B2: 0B1505719 | C2: Nguyễn Phước Hiếu | D2: 0.45 | E2: 0.25 | F2: 0.3 | G2: 0.5 | H2: 4.2 | I2: 4 | J2: 5 | K2: D+
A3: 2 | B3: 1B1505915 | C3: Lý Minh Trí | D3: 0.5 | E3: 0.35 | F3: 0.4 | G3: 1 | H3: 5.8 | I3: 5.7 | J3: 6.2 | K3: C
A4: 3 | B4: 0B1509874 | C4: Nguyễn Kiều Mi | D4: 0.25 | E4: 0.25 | F4: 0.3 | G4: 0.5 | H4: 5.8 | I4: 4.8 | J4: 5.8 | K4: C
A5: 4 | B5: 0B1509929 | C5: Đặng Duy Linh | D5: 0.4 | E5: 0.25 | F5: 0.35 | G5: 1 | H5: 4.5 | I5: 4.7 | J5: 5.7 | K5: C
A6: 5 | B6: 2B1605223 | C6: Lê Thị Trúc Linh | D6: 0.45 | E6: 0.4 | F6: 0.35 | G6: 0.75 | H6: 5.5 | I6: 5.3 | J6: 5.6 | K6: C
A7: 7 | B7: 0B1605249 | C7: Lê Minh Thông | D7: 0.4 | E7: 0.4 | F7: 0.4 | G7: 1 | H7: 5.3 | I7: 5.4 | J7: 6.4 | K7: C
A8: 9 | B8: 3B1605281 | C8: Trần Thị Kim Khoa | D8: 0.5 | E8: 0.4 | F8: 0.4 | G8: 1 | H8: -3 | I8: 0 | J8: 0 | K8: F
A9: 10 | B9: 0B1605285 | C9: Huỳnh Thị Hồng Loan | D9: 0.45 | E9: 0.4 | F9: 0.45 | G9: 0 | H9: 6.8 | I9: 5.4 | J9: 0 | K9: F
A10: 11 | B10: 0B1605291 | C10: Trần Thị Thanh Nguyên | D10: 0.45 | E10: 0.4 | F10: 0.4 | G10: 0.75 | H10: 6.3 | I10: 5.8 | J10: 6.8 | K10: C+
A11: 13 | B11: 0B1606845 | C11: Vũ Mạnh Thắng | D11: 0.4 | E11: 0.5 | F11: 0.5 | G11: 1.2 | H11: 5.5 | I11: 5.9 | J11: 6.9 | K11: C+
A12: 14 | B12: 0B1607017 | C12: Cao Ngọc Quyên | D12: 0.5 | E12: 0.5 | F12: 0.45 | G12: 0.3 | H12: 6 | I12: 5.4 | J12: 6.4 | K12: C
A13: 15 | B13: 4B1607025 | C13: Nguyễn Chí Thanh | D13: 0.4 | E13: 0.45 | F13: 0.4 | G13: 0.3 | H13: -3 | I13: 0 | J13: 0 | K13: F
... A27: 39 | B27: 1B1709313 | C27: Võ Thị Thùy Trang | D27: 0.4 | E27: 0.4 | F27: 0.4 | G27: 0.75 | H27: 3.2 | I27: 3.9 | J27: 4.4 | K27: D

Sheet Sinh viên >=7
A1: STT | B1: Mã SV | C1: Họ và Tên | D1: Điểm TH 1 | E1: Điểm TH 2 | F1: Điểm TH 3 | G1: Điểm BT lớn | H1: Điểm LT | I1: Điểm tổng | J1: Điểm theo thang điểm 10 | K1: Điểm chữ
A2: 6 | B2: 0B1605235 | C2: Phạm Thị Huỳnh Như | D2: 0.4 | E2: 0.45 | F2: 0.5 | G2: 1.2 | H2: 7.5 | I2: 7.1 | J2: 8.1 | K2: B+
A3: 23 | B3: 0B1706555 | C3: Lê Hồng Quốc Vương | D3: 0.5 | E3: 0.5 | F3: 0.5 | G3: 1.5 | H3: 7.5 | I3: 7.5 | J3: 8.5 | K3: B+
A4: 24 | B4: 2B1706560 | C4: Huỳnh Hoàng Ẩn | D4: 0.45 | E4: 0.3 | F4: 0.45 | G4: 1.2 | H4: 8.8 | I4: 7.7 | J4: 8 | K4: B+
A5: 27 | B5: 0B1706606 | C5: Ngụy Hữu Lộc | D5: 0.5 | E5: 0.4 | F5: 0.45 | G5: 1.5 | H5: 8.8 | I5: 8.1 | J5: 9.1 | K5: A
A6: 28 | B6: 0B1706610 | C6: Nguyễn Trà Mi | D6: 0.5 | E6: 0.45 | F6: 0.45 | G6: 1 | H6: 7.8 | I6: 7.1 | J6: 8.1 | K6: B+
A7: 31 | B7: 0B1706633 | C7: Trần Thị Hoàng Quyên | D7: 0.4 | E7: 0.5 | F7: 0.5 | G7: 1 | H7: 9.2 | I7: 7.9 | J7: 8.9 | K7: B+
